Workbook

Sheet Dashboard

Sheet KPI's & Pivot Tables
A1: Total Leads | B1: Hot Leads | C1: Warm Leads | D1: Cold Leads | E1: Avg Lead Score | F1: Total Campaign Spend | G1: Avg Cost Per Lead | H1: Avg ROAS
A2: =COUNTA(scoring_results!A2:A1001) -> 1000 | B2: =COUNTIF(scoring_results!M2:M1001,"HOT") -> 110 | C2: =COUNTIF(scoring_results!M2:M1001,"WARM") -> 537 | D2: =COUNTIF(scoring_results!M2:M1001,"COLD") -> 353 | E2: =ROUND(AVERAGE(scoring_results!L2:L1001),1) -> 41 | F2: =SUM(clean_spend!F:F) -> 758451 | G2: =ROUND(AVERAGE(clean_spend!M:M),2) -> 184.62 | H2: =ROUND(AVERAGE(clean_spend!Q:Q),2) -> 4.93
A8: Source | B8: Count of Leads | D8: Segment | E8: Count of Leads | H8: Industry | I8: Count of Leads
A9: COLD_EMAIL | B9: 109 | D9: COLD | E9: 353 | H9: AI/ML | I9: 45
A10: CONTENT_SYNDICATION | B10: 55 | D10: HOT | E10: 110 | H10: Automotive | I10: 34
A11: DIRECT | B11: 83 | D11: WARM | E11: 537 | H11: Biotech | I11: 43
A12: EVENT | B12: 99 | D12: Grand Total | E12: 1000 | H12: Cleantech | I12: 33
A13: ORGANIC | B13: 121 | H13: Cybersecurity | I13: 56
A14: PAID | B14: 109 | H14: Devops | I14: 35
A15: PARTNER | B15: 85 | H15: E-Commerce | I15: 49
A16: REFERRAL | B16: 107 | H16: Edtech | I16: 48
A17: SOCIAL | B17: 112 | H17: Energy | I17: 45
A18: UNKNOWN | B18: 52 | H18: Fintech | I18: 55
A19: WEBINAR | B19: 68 | D19: Campaign | E19: Sum of Monthly Spend | F19: Sum of Revenue Attributed | H19: Gaming | I19: 22
A20: Grand Total | B20: 1000 | D20: Cold Email Outbound | E20: 63789 | F20: 195264 | H20: Healthcare | I20: 54
D21: Content Syndication | E21: 56772 | F21: 78482 | H21: Hrtech | I21: 41
D22: Google Ads - Display | E22: 56723 | F22: 173580 | H22: Insurtech | I22: 30
D23: Google Ads - Search | E23: 93070 | F23: 339161 | H23: Legal Tech | I23: 24
D24: LinkedIn - ABM Campaign | E24: 108375 | F24: 202263 | H24: Logistics | I24: 53
D25: Meta - Brand Awareness | E25: 89830 | F25: 293248 | H25: Manufacturing | I25: 28
D26: Referral Program | E26: 37889 | F26: 364131 | H26: Martech | I26: 45
A27: Month | B27: Sum of Monthly spend | D27: SEO Content Program | E27: 46997 | F27: 634186 | H27: Media | I27: 26
A28: 2025-01 | B28: 52949 | D28: Trade Show Circuit | E28: 130023 | F28: 170542 | H28: Proptech | I28: 30
A29: 2025-02 | B29: 50794 | D29: Webinar Series | E29: 74983 | F29: 551435 | H29: Retail | I29: 52
A30: 2025-03 | B30: 64081 | D30: Grand Total | E30: 758451 | F30: 3002292 | H30: Saas | I30: 49
A31: 2025-04 | B31: 53201 | H31: Supply Chain | I31: 26
A32: 2025-05 | B32: 57309 | H32: Telecom | I32: 34
A33: 2025-06 | B33: 54630 | H33: Unknown | I33: 43
A34: 2025-07 | B34: 57655 | H34: Grand Total | I34: 1000
A35: 2025-08 | B35: 58293
A36: 2025-09 | B36: 59319
A37: 2025-10 | B37: 80743 | D37: Score Bucket | E37: Count of Leads
A38: 2025-11 | B38: 71190 | D38: 0-19 | E38: 91
A39: 2025-12 | B39: 98287 | D39: 20-39 | E39: 395
A40: Grand Total | B40: 758451 | D40: 40-59 | E40: 404 | H40: Name | I40: Total score
D41: 60-79 | E41: 108 | H41: Maya Chen | I41: 135
D42: 80-100 | E42: 2 | H42: Raphael Park | I42: 110.1
D43: Grand Total | E43: 1000 | H43: Wendy Chandra | I43: 103
H44: Nico Nakamura | I44: 97.6
H45: Hugo Bianchi | I45: 93.5
...

Sheet scoring_results
A1: lead_id | B1: name | C1: company | D1: source | E1: company_size | F1: email_opens_score | G1: clicks_score | H1: visits_score | I1: demo_score | J1: size_score | K1: engagement_score | L1: TOTAL_SCORE | M1: segment | N1: recommended_action | O1: score_bucket
A2: {=model!A2:A1001} -> L0001 | B2: {=model!B2:B1001} -> Liora Jackson | C2: {=model!C2:C1001} -> AIRTABLE | D2: {=model!E2:E1001} -> UNKNOWN | E2: {=model!D2:D1001} -> SMB | F2: =ROUND(IFERROR(model!I2/scoring_weights!$C$2,0)*scoring_weights!$B$2,1) -> 10 | G2: =ROUND(IFERROR(model!J2/scoring_weights!$C$3,0)*scoring_weights!$B$3,1) -> 15 | H2: =ROUND(IFERROR(model!K2/scoring_weights!$C$4,0)*scoring_weights!$B$4,1) -> 4.3 | I2: =IF(model!L2="YES",scoring_weights!$B$5,0) -> 0 | J2: =IF(model!D2="ENTERPRISE",scoring_weights!$B$6,IF(model!D2="MID-MARKET",scoring_weights!$B$6*0.75,IF(model!D2="SMB",scoring_weights!$B$6*0.5,IF(model!D2="STARTUP",scoring_weights!$B$6*0.25,0)))) -> 7.5 | K2: =ROUND(MIN(IFERROR((model!O2/10+model!P2/5+model!R2*2+model!T2+model!U2*1.5)/6,0),1)*scoring_weights!$B$7,1) -> 18 | L2: =ROUND(F2+G2+H2+I2+J2+K2,1) -> 54.8 | M2: =IF(L2>=segment_thresholds!$B$2,"HOT",IF(L2>=segment_thresholds!$B$3,"WARM","COLD")) -> WARM | N2: =IF(M2="HOT","Schedule Call",IF(M2="WARM","Nurture Email Drip","Retarget with Ads")) -> Nurture Email Drip | O2: =IF(L2<20,"0-19",IF(L2<40,"20-39",IF(L2<60,"40-59",IF(L2<80,"60-79","80-100")))) -> 40-59
A3: L0002 | B3: Yara Malik | C3: AIRTABLE | D3: EVENT | E3: SMB | F3: =ROUND(IFERROR(model!I3/scoring_weights!$C$2,0)*scoring_weights!$B$2,1) -> 1.1 | G3: =ROUND(IFERROR(model!J3/scoring_weights!$C$3,0)*scoring_weights!$B$3,1) -> 0 | H3: =ROUND(IFERROR(model!K3/scoring_weights!$C$4,0)*scoring_weights!$B$4,1) -> 3 | I3: =IF(model!L3="YES",scoring_weights!$B$5,0) -> 20 | J3: =IF(model!D3="ENTERPRISE",scoring_weights!$B$6,IF(model!D3="MID-MARKET",scoring_weights!$B$6*0.75,IF(model!D3="SMB",scoring_weights!$B$6*0.5,IF(model!D3="STARTUP",scoring_weights!$B$6*0.25,0)))) -> 7.5 | K3: =ROUND(MIN(IFERROR((model!O3/10+model!P3/5+model!R3*2+model!T3+model!U3*1.5)/6,0),1)*scoring_weights!$B$7,1) -> 1.5 | L3: =ROUND(F3+G3+H3+I3+J3+K3,1) -> 33.1 | M3: =IF(L3>=segment_thresholds!$B$2,"HOT",IF(L3>=segment_thresholds!$B$3,"WARM","COLD")) -> COLD | N3: =IF(M3="HOT","Schedule Call",IF(M3="WARM","Nurture Email Drip","Retarget with Ads")) -> Retarget with Ads | O3: =IF(L3<20,"0-19",IF(L3<40,"20-39",IF(L3<60,"40-59",IF(L3<80,"60-79","80-100")))) -> 20-39
A4: L0003 | B4: Luna Harris | C4: CROWD STRIKE | D4: EVENT | E4: SMB | F4: =ROUND(IFERROR(model!I4/scoring_weights!$C$2,0)*scoring_weights!$B$2,1) -> 3.7 | G4: =ROUND(IFERROR(model!J4/scoring_weights!$C$3,0)*scoring_weights!$B$3,1) -> 13.5 | H4: =ROUND(IFERROR(model!K4/scoring_weights!$C$4,0)*scoring_weights!$B$4,1) -> 3.3 | I4: =IF(model!L4="YES",scoring_weights!$B$5,0) -> 20 | J4: =IF(model!D4="ENTERPRISE",scoring_weights!$B$6,IF(model!D4="MID-MARKET",scoring_weights!$B$6*0.75,IF(model!D4="SMB",scoring_weights!$B$6*0.5,IF(model!D4="STARTUP",scoring_weights!$B$6*0.25,0)))) -> 7.5 | K4: =ROUND(MIN(IFERROR((model!O4/10+model!P4/5+model!R4*2+model!T4+model!U4*1.5)/6,0),1)*scoring_weights!$B$7,1) -> 9.5 | L4: =ROUND(F4+G4+H4+I4+J4+K4,1) -> 57.5 | M4: =IF(L4>=segment_thresholds!$B$2,"HOT",IF(L4>=segment_thresholds!$B$3,"WARM","COLD")) -> WARM | N4: =IF(M4="HOT","Schedule Call",IF(M4="WARM","Nurture Email Drip","Retarget with Ads")) -> Nurture Email Drip | O4: =IF(L4<20,"0-19",IF(L4<40,"20-39",IF(L4<60,"40-59",IF(L4<80,"60-79","80-100")))) -> 40-59
A5: L0004 | B5: James Nakamura | C5: HUB SPOT | D5: PARTNER | E5: STARTUP | F5: =ROUND(IFERROR(model!I5/scoring_weights!$C$2,0)*scoring_weights!$B$2,1) -> 10 | G5: =ROUND(IFERROR(model!J5/scoring_weights!$C$3,0)*scoring_weights!$B$3,1) -> 0 | H5: =ROUND(IFERROR(model!K5/scoring_weights!$C$4,0)*scoring_weights!$B$4,1) -> 1.2 | I5: =IF(model!L5="YES",scoring_weights!$B$5,0) -> 0 | J5: =IF(model!D5="ENTERPRISE",scoring_weights!$B$6,IF(model!D5="MID-MARKET",scoring_weights!$B$6*0.75,IF(model!D5="SMB",scoring_weights!$B$6*0.5,IF(model!D5="STARTUP",scoring_weights!$B$6*0.25,0)))) -> 3.75 | K5: =ROUND(MIN(IFERROR((model!O5/10+model!P5/5+model!R5*2+model!T5+model!U5*1.5)/6,0),1)*scoring_weights!$B$7,1) -> 11 | L5: =ROUND(F5+G5+H5+I5+J5+K5,1) -> 26 | M5: =IF(L5>=segment_thresholds!$B$2,"HOT",IF(L5>=segment_thresholds!$B$3,"WARM","COLD")) -> COLD | N5: =IF(M5="HOT","Schedule Call",IF(M5="WARM","Nurture Email Drip","Retarget with Ads")) -> Retarget with Ads | O5: =IF(L5<20,"0-19",IF(L5<40,"20-39",IF(L5<60,"40-59",IF(L5<80,"60-79","80-100")))) -> 20-39
A6: L0005 | B6: Bastian Mishra | C6: DROPBOX | D6: UNKNOWN | E6: SMB | F6: =ROUND(IFERROR(model!I6/scoring_weights!$C$2,0)*scoring_weights!$B$2,1) -> 0 | G6: =ROUND(IFERROR(model!J6/scoring_weights!$C$3,0)*scoring_weights!$B$3,1) -> 6.8 | H6: =ROUND(IFERROR(model!K6/scoring_weights!$C$4,0)*scoring_weights!$B$4,1) -> 2.5 | I6: =IF(model!L6="YES",scoring_weights!$B$5,0) -> 20 | J6: =IF(model!D6="ENTERPRISE",scoring_weights!$B$6,IF(model!D6="MID-MARKET",scoring_weights!$B$6*0.75,IF(model!D6="SMB",scoring_weights!$B$6*0.5,IF(model!D6="STARTUP",scoring_weights!$B$6*0.25,0)))) -> 7.5 | K6: =ROUND(MIN(IFERROR((model!O6/10+model!P6/5+model!R6*2+model!T6+model!U6*1.5)/6,0),1)*scoring_weights!$B$7,1) -> 16.5 | L6: =ROUND(F6+G6+H6+I6+J6+K6,1) -> 53.3 | M6: =IF(L6>=segment_thresholds!$B$2,"HOT",IF(L6>=segment_thresholds!$B$3,"WARM","COLD")) -> WARM | N6: =IF(M6="HOT","Schedule Call",IF(M6="WARM","Nurture Email Drip","Retarget with Ads")) -> Nurture Email Drip | O6: =IF(L6<20,"0-19",IF(L6<40,"20-39",IF(L6<60,"40-59",IF(L6<80,"60-79","80-100")))) -> 40-59
A7: L0006 | B7: Yuki Robinson | C7: CLOUDFLARE | D7: ORGANIC | E7: SMB | F7: =ROUND(IFERROR(model!I7/scoring_weights!$C$2,0)*scoring_weights!$B$2,1) -> 4 | G7: =ROUND(IFERROR(model!J7/scoring_weights!$C$3,0)*scoring_weights!$B$3,1) -> 0 | H7: =ROUND(IFERROR(model!K7/scoring_weights!$C$4,0)*scoring_weights!$B$4,1) -> 0 | I7: =IF(model!L7="YES",scoring_weights!$B$5,0) -> 20 | J7: =IF(model!D7="ENTERPRISE",scoring_weights!$B$6,IF(model!D7="MID-MARKET",scoring_weights!$B$6*0.75,IF(model!D7="SMB",scoring_weights!$B$6*0.5,IF(model!D7="STARTUP",scoring_weights!$B$6*0.25,0)))) -> 7.5 | K7: =ROUND(MIN(IFERROR((model!O7/10+model!P7/5+model!R7*2+model!T7+model!U7*1.5)/6,0),1)*scoring_weights!$B$7,1) -> 11 | L7: =ROUND(F7+G7+H7+I7+J7+K7,1) -> 42.5 | M7: =IF(L7>=segment_thresholds!$B$2,"HOT",IF(L7>=segment_thresholds!$B$3,"WARM","COLD")) -> WARM | N7: =IF(M7="HOT","Schedule Call",IF(M7="WARM","Nurture Email Drip","Retarget with Ads")) -> Nurture Email Drip | O7: =IF(L7<20,"0-19",IF(L7<40,"20-39",IF(L7<60,"40-59",IF(L7<80,"60-79","80-100")))) -> 40-59
A8: L0007 | B8: Uriel Jensen | C8: STRIPE INC | D8: COLD_EMAIL | E8: STARTUP | F8: =ROUND(IFERROR(model!I8/scoring_weights!$C$2,0)*scoring_weights!$B$2,1) -> 1.7 | G8: =ROUND(IFERROR(model!J8/scoring_weights!$C$3,0)*scoring_weights!$B$3,1) -> 4.5 | H8: =ROUND(IFERROR(model!K8/scoring_weights!$C$4,0)*scoring_weights!$B$4,1) -> 1.3 | I8: =IF(model!L8="YES",scoring_weights!$B$5,0) -> 0 | J8: =IF(model!D8="ENTERPRISE",scoring_weights!$B$6,IF(model!D8="MID-MARKET",scoring_weights!$B$6*0.75,IF(model!D8="SMB",scoring_weights!$B$6*0.5,IF(model!D8="STARTUP",scoring_weights!$B$6*0.25,0)))) -> 3.75 | K8: =ROUND(MIN(IFERROR((model!O8/10+model!P8/5+model!R8*2+model!T8+model!U8*1.5)/6,0),1)*scoring_weights!$B$7,1) -> 19 | L8: =ROUND(F8+G8+H8+I8+J8+K8,1) -> 30.3 | M8: =IF(L8>=segment_thresholds!$B$2,"HOT",IF(L8>=segment_thresholds!$B$3,"WARM","COLD")) -> COLD | N8: =IF(M8="HOT","Schedule Call",IF(M8="WARM","Nurture Email Drip","Retarget with Ads")) -> Retarget with Ads | O8: =IF(L8<20,"0-19",IF(L8<40,"20-39",IF(L8<60,"40-59",IF(L8<80,"60-79","80-100")))) -> 20-39
A9: L0008 | B9: Vivian Young | C9: GOOGLE | D9: SOCIAL | E9: MID-MARKET | F9: =ROUND(IFERROR(model!I9/scoring_weights!$C$2,0)*scoring_weights!$B$2,1) -> 0.9 | G9: =ROUND(IFERROR(model!J9/scoring_weights!$C$3,0)*scoring_weights!$B$3,1) -> 12.8 | H9: =ROUND(IFERROR(model!K9/scoring_weights!$C$4,0)*scoring_weights!$B$4,1) -> 0 | I9: =IF(model!L9="YES",scoring_weights!$B$5,0) -> 20 | J9: =IF(model!D9="ENTERPRISE",scoring_weights!$B$6,IF(model!D9="MID-MARKET",scoring_weights!$B$6*0.75,IF(model!D9="SMB",scoring_weights!$B$6*0.5,IF(model!D9="STARTUP",scoring_weights!$B$6*0.25,0)))) -> 11.25 | K9: =ROUND(MIN(IFERROR((model!O9/10+model!P9/5+model!R9*2+model!T9+model!U9*1.5)/6,0),1)*scoring_weights!$B$7,1) -> 6 | L9: =ROUND(F9+G9+H9+I9+J9+K9,1) -> 51 | M9: =IF(L9>=segment_thresholds!$B$2,"HOT",IF(L9>=segment_thresholds!$B$3,"WARM","COLD")) -> WARM | N9: =IF(M9="HOT","Schedule Call",IF(M9="WARM","Nurture Email Drip","Retarget with Ads")) -> Nurture Email Drip | O9: =IF(L9<20,"0-19",IF(L9<40,"20-39",IF(L9<60,"40-59",IF(L9<80,"60-79","80-100")))) -> 40-59
A10: L0009 | B10: Elena Pandey | C10: ELASTIC | D10: EVENT | E10: SMB | F10: =ROUND(IFERROR(model!I10/scoring_weights!$C$2,0)*scoring_weights!$B$2,1) -> 5.4 | G10: =ROUND(IFERROR(model!J10/scoring_weights!$C$3,0)*scoring_weights!$B$3,1) -> 1.5 | H10: =ROUND(IFERROR(model!K10/scoring_weights!$C$4,0)*scoring_weights!$B$4,1) -> 0 | I10: =IF(model!L10="YES",scoring_weights!$B$5,0) -> 0 | J10: =IF(model!D10="ENTERPRISE",scoring_weights!$B$6,IF(model!D10="MID-MARKET",scoring_weights!$B$6*0.75,IF(model!D10="SMB",scoring_weights!$B$6*0.5,IF(model!D10="STARTUP",scoring_weights!$B$6*0.25,0)))) -> 7.5 | K10: =ROUND(MIN(IFERROR((model!O10/10+model!P10/5+model!R10*2+model!T10+model!U10*1.5)/6,0),1)*scoring_weights!$B$7,1) -> 4.5 | L10: =ROUND(F10+G10+H10+I10+J10+K10,1) -> 18.9 | M10: =IF(L10>=segment_thresholds!$B$2,"HOT",IF(L10>=segment_thresholds!$B$3,"WARM","COLD")) -> COLD | N10: =IF(M10="HOT","Schedule Call",IF(M10="WARM","Nurture Email Drip","Retarget with Ads")) -> Retarget with Ads | O10: =IF(L10<20,"0-19",IF(L10<40,"20-39",IF(L10<60,"40-59",IF(L10<80,"60-79","80-100")))) -> 0-19
A11: L0010 | B11: Priya Muller | C11: PALO ALTO | D11: PAID | E11: MID-MARKET | F11: =ROUND(IFERROR(model!I11/scoring_weights!$C$2,0)*scoring_weights!$B$2,1) -> 2.6 | G11: =ROUND(IFERROR(model!J11/scoring_weights!$C$3,0)*scoring_weights!$B$3,1) -> 14.3 | H11: =ROUND(IFERROR(model!K11/scoring_weights!$C$4,0)*scoring_weights!$B$4,1) -> 3.5 | I11: =IF(model!L11="YES",scoring_weights!$B$5,0) -> 20 | J11: =IF(model!D11="ENTERPRISE",scoring_weights!$B$6,IF(model!D11="MID-MARKET",scoring_weights!$B$6*0.75,IF(model!D11="SMB",scoring_weights!$B$6*0.5,IF(model!D11="STARTUP",scoring_weights!$B$6*0.25,0)))) -> 11.25 | K11: =ROUND(MIN(IFERROR((model!O11/10+model!P11/5+model!R11*2+model!T11+model!U11*1.5)/6,0),1)*scoring_weights!$B$7,1) -> 5.5 | L11: =ROUND(F11+G11+H11+I11+J11+K11,1) -> 57.2 | M11: =IF(L11>=segment_thresholds!$B$2,"HOT",IF(L11>=segment_thresholds!$B$3,"WARM","COLD")) -> WARM | N11: =IF(M11="HOT","Schedule Call",IF(M11="WARM","Nurture Email Drip","Retarget with Ads")) -> Nurture Email Drip | O11: =IF(L11<20,"0-19",IF(L11<40,"20-39",IF(L11<60,"40-59",IF(L11<80,"60-79","80-100")))) -> 40-59
A12: L0011 | B12: Landon Rossi | C12: CROWD STRIKE | D12: EVENT | E12: SMB | F12: =ROUND(IFERROR(model!I12/scoring_weights!$C$2,0)*scoring_weights!$B$2,1) -> 0.6 | G12: =ROUND(IFERROR(model!J12/scoring_weights!$C$3,0)*scoring_weights!$B$3,1) -> 4.5 | H12: =ROUND(IFERROR(model!K12/scoring_weights!$C$4,0)*scoring_weights!$B$4,1) -> 7 | I12: =IF(model!L12="YES",scoring_weights!$B$5,0) -> 0 | J12: =IF(model!D12="ENTERPRISE",scoring_weights!$B$6,IF(model!D12="MID-MARKET",scoring_weights!$B$6*0.75,IF(model!D12="SMB",scoring_weights!$B$6*0.5,IF(model!D12="STARTUP",scoring_weights!$B$6*0.25,0)))) -> 7.5 | K12: =ROUND(MIN(IFERROR((model!O12/10+model!P12/5+model!R12*2+model!T12+model!U12*1.5)/6,0),1)*scoring_weights!$B$7,1) -> 16 | L12: =ROUND(F12+G12+H12+I12+J12+K12,1) -> 35.6 | M12: =IF(L12>=segment_thresholds!$B$2,"HOT",IF(L12>=segment_thresholds!$B$3,"WARM","COLD")) -> WARM | N12: =IF(M12="HOT","Schedule Call",IF(M12="WARM","Nurture Email Drip","Retarget with Ads")) -> Nurture Email Drip | O12: =IF(L12<20,"0-19",IF(L12<40,"20-39",IF(L12<60,"40-59",IF(L12<80,"60-79","80-100")))) -> 20-39
A13: L0012 | B13: Jamal Soto | C13: NOTION | D13: COLD_EMAIL | E13: N/A | F13: =ROUND(IFERROR(model!I13/scoring_weights!$C$2,0)*scoring_weights!$B$2,1) -> 4 | G13: =ROUND(IFERROR(model!J13/scoring_weights!$C$3,0)*scoring_weights!$B$3,1) -> 4.5 | H13: =ROUND(IFERROR(model!K13/scoring_weights!$C$4,0)*scoring_weights!$B$4,1) -> 2.8 | I13: =IF(model!L13="YES",scoring_weights!$B$5,0) -> 20 | J13: =IF(model!D13="ENTERPRISE",scoring_weights!$B$6,IF(model!D13="MID-MARKET",scoring_weights!$B$6*0.75,IF(model!D13="SMB",scoring_weights!$B$6*0.5,IF(model!D13="STARTUP",scoring_weights!$B$6*0.25,0)))) -> 0 | K13: =ROUND(MIN(IFERROR((model!O13/10+model!P13/5+model!R13*2+model!T13+model!U13*1.5)/6,0),1)*scoring_weights!$B$7,1) -> 30 | L13: =ROUND(F13+G13+H13+I13+J13+K13,1) -> 61.3 | M13: =IF(L13>=segment_thresholds!$B$2,"HOT",IF(L13>=segment_thresholds!$B$3,"WARM","COLD")) -> HOT | N13: =IF(M13="HOT","Schedule Call",IF(M13="WARM","Nurture Email Drip","Retarget with Ads")) -> Schedule Call | O13: =IF(L13<20,"0-19",IF(L13<40,"20-39",IF(L13<60,"40-59",IF(L13<80,"60-79","80-100")))) -> 60-79
A14: L0013 | B14: Julian Shah | C14: DROPBOX | D14: ORGANIC | E14: STARTUP | F14: =ROUND(IFERROR(model!I14/scoring_weights!$C$2,0)*scoring_weights!$B$2,1) -> 9.7 | G14: =ROUND(IFERROR(model!J14/scoring_weights!$C$3,0)*scoring_weights!$B$3,1) -> 4.5 | H14: =ROUND(IFERROR(model!K14/scoring_weights!$C$4,0)*scoring_weights!$B$4,1) -> 0.7 | I14: =IF(model!L14="YES",scoring_weights!$B$5,0) -> 0 | J14: =IF(model!D14="ENTERPRISE",scoring_weights!$B$6,IF(model!D14="MID-MARKET",scoring_weights!$B$6*0.75,IF(model!D14="SMB",scoring_weights!$B$6*0.5,IF(model!D14="STARTUP",scoring_weights!$B$6*0.25,0)))) -> 3.75 | K14: =ROUND(MIN(IFERROR((model!O14/10+model!P14/5+model!R14*2+model!T14+model!U14*1.5)/6,0),1)*scoring_weights!$B$7,1) -> 13 | L14: =ROUND(F14+G14+H14+I14+J14+K14,1) -> 31.7 | M14: =IF(L14>=segment_thresholds!$B$2,"HOT",IF(L14>=segment_thresholds!$B$3,"WARM","COLD")) -> COLD | N14: =IF(M14="HOT","Schedule Call",IF(M14="WARM","Nurture Email Drip","Retarget with Ads")) -> Retarget with Ads | O14: =IF(L14<20,"0-19",IF(L14<40,"20-39",IF(L14<60,"40-59",IF(L14<80,"60-79","80-100")))) -> 20-39
... A1001: L1000 | B1001: Leo Taylor | C1001: HUBSPOT | D1001: ORGANIC | E1001: SMB | F1001: =ROUND(IFERROR(model!I1001/scoring_weights!$C$2,0)*scoring_weights!$B$2,1) -> 6.9 | G1001: =ROUND(IFERROR(model!J1001/scoring_weights!$C$3,0)*scoring_weights!$B$3,1) -> 10.5 | H1001: =ROUND(IFERROR(model!K1001/scoring_weights!$C$4,0)*scoring_weights!$B$4,1) -> 0.8 | I1001: =IF(model!L1001="YES",scoring_weights!$B$5,0) -> 0 | J1001: =IF(model!D1001="ENTERPRISE",scoring_weights!$B$6,IF(model!D1001="MID-MARKET",scoring_weights!$B$6*0.75,IF(model!D1001="SMB",scoring_weights!$B$6*0.5,IF(model!D1001="STARTUP",scoring_weights!$B$6*0.25,0)))) -> 7.5 | K1001: =ROUND(MIN(IFERROR((model!O1001/10+model!P1001/5+model!R1001*2+model!T1001+model!U1001*1.5)/6,0),1)*scoring_weights!$B$7,1) -> 5 | L1001: =ROUND(F1001+G1001+H1001+I1001+J1001+K1001,1) -> 30.7 | M1001: =IF(L1001>=segment_thresholds!$B$2,"HOT",IF(L1001>=segment_thresholds!$B$3,"WARM","COLD")) -> COLD | N1001: =IF(M1001="HOT","Schedule Call",IF(M1001="WARM","Nurture Email Drip","Retarget with Ads")) -> Retarget with Ads | O1001: =IF(L1001<20,"0-19",IF(L1001<40,"20-39",IF(L1001<60,"40-59",IF(L1001<80,"60-79","80-100")))) -> 20-39

Sheet model
A1: lead_id | B1: name | C1: company | D1: company_size | E1: source | F1: industry | G1: job_title | H1: country | I1: email_opens | J1: clicks | K1: website_visits | L1: demo_requested | M1: lead_status | N1: data_quality | O1: total_interactions | P1: high_engagement | Q1: total_time_mins | R1: demo_requests | S1: content_downloads | T1: webinars_attended | U1: pricing_page_views | V1: source_total_spend | W1: source_total_leads | X1: source_cost_per_lead | Y1: source_roas
A2: {=clean_leads!A2:A1001} -> L0001 | B2: {=clean_leads!B2:B1001} -> Liora Jackson | C2: {=clean_leads!E2:E1001} -> AIRTABLE | D2: {=clean_leads!F2:F1001} -> SMB | E2: {=clean_leads!G2:G1001} -> UNKNOWN | F2: {=clean_leads!N2:N1001} -> Saas | G2: {=clean_leads!O2:O1001} -> Product Manager | H2: {=clean_leads!P2:P1001} -> Thailand | I2: {=clean_leads!H2:H1001} -> 35 | J2: {=clean_leads!I2:I1001} -> 20 | K2: {=clean_leads!J2:J1001} -> 26 | L2: {=clean_leads!K2:K1001} -> NO | M2: {=clean_leads!M2:M1001} -> ENGAGED | N2: =IF(COUNTBLANK(clean_leads!B2:S2)>=8,"LOW",IF(COUNTBLANK(clean_leads!B2:S2)>=4,"MEDIUM","HIGH")) -> HIGH | O2: =COUNTIF(clean_interactions!B:B,A2) -> 6 | P2: =COUNTIFS(clean_interactions!B:B,A2,clean_interactions!N:N,"HIGH") -> 5 | Q2: =ROUND(SUMIF(clean_interactions!B:B,A2,clean_interactions!M:M),1) -> 125.4 | R2: =COUNTIFS(clean_interactions!B:B,A2,clean_interactions!C:C,"DEMO_REQUEST") -> 1 | S2: =COUNTIFS(clean_interactions!B:B,A2,clean_interactions!C:C,"CONTENT_DOWNLOAD") -> 0 | T2: =COUNTIFS(clean_interactions!B:B,A2,clean_interactions!C:C,"WEBINAR_ATTENDED") -> 0 | U2: =COUNTIFS(clean_interactions!B:B,A2,clean_interactions!C:C,"PRICING_PAGE_VIEW") -> 0 | V2: =SUMIF(clean_spend!D:D,E2,clean_spend!F:F) -> 0 | W2: =SUMIF(clean_spend!D:D,E2,clean_spend!J:J) -> 0 | X2: =IFERROR(V2/W2,0) -> 0 | Y2: =IFERROR(SUMIF(clean_spend!D:D,E2,clean_spend!L:L)/V2,0) -> 0
A3: L0002 | B3: Yara Malik | C3: AIRTABLE | D3: SMB | E3: EVENT | F3: Retail | G3: Sales Engineer | H3: IN | I3: 4 | J3: 0 | K3: 18 | L3: YES | M3: QUALIFIED | N3: =IF(COUNTBLANK(clean_leads!B3:S3)>=8,"LOW",IF(COUNTBLANK(clean_leads!B3:S3)>=4,"MEDIUM","HIGH")) -> HIGH | O3: =COUNTIF(clean_interactions!B:B,A3) -> 1 | P3: =COUNTIFS(clean_interactions!B:B,A3,clean_interactions!N:N,"HIGH") -> 1 | Q3: =ROUND(SUMIF(clean_interactions!B:B,A3,clean_interactions!M:M),1) -> 32.4 | R3: =COUNTIFS(clean_interactions!B:B,A3,clean_interactions!C:C,"DEMO_REQUEST") -> 0 | S3: =COUNTIFS(clean_interactions!B:B,A3,clean_interactions!C:C,"CONTENT_DOWNLOAD") -> 0 | T3: =COUNTIFS(clean_interactions!B:B,A3,clean_interactions!C:C,"WEBINAR_ATTENDED") -> 0 | U3: =COUNTIFS(clean_interactions!B:B,A3,clean_interactions!C:C,"PRICING_PAGE_VIEW") -> 0 | V3: =SUMIF(clean_spend!D:D,E3,clean_spend!F:F) -> 130023 | W3: =SUMIF(clean_spend!D:D,E3,clean_spend!J:J) -> 322 | X3: =IFERROR(V3/W3,0) -> 403.79814 | Y3: =IFERROR(SUMIF(clean_spend!D:D,E3,clean_spend!L:L)/V3,0) -> 1.3116295
A4: L0003 | B4: Luna Harris | C4: CROWD STRIKE | D4: SMB | E4: EVENT | F4: AI/ML | G4: Business Development Rep | H4: AU | I4: 13 | J4: 18 | K4: 20 | L4: YES | M4: QUALIFIED | N4: =IF(COUNTBLANK(clean_leads!B4:S4)>=8,"LOW",IF(COUNTBLANK(clean_leads!B4:S4)>=4,"MEDIUM","HIGH")) -> HIGH | O4: =COUNTIF(clean_interactions!B:B,A4) -> 7 | P4: =COUNTIFS(clean_interactions!B:B,A4,clean_interactions!N:N,"HIGH") -> 6 | Q4: =ROUND(SUMIF(clean_interactions!B:B,A4,clean_interactions!M:M),1) -> 136.8 | R4: =COUNTIFS(clean_interactions!B:B,A4,clean_interactions!C:C,"DEMO_REQUEST") -> 0 | S4: =COUNTIFS(clean_interactions!B:B,A4,clean_interactions!C:C,"CONTENT_DOWNLOAD") -> 1 | T4: =COUNTIFS(clean_interactions!B:B,A4,clean_interactions!C:C,"WEBINAR_ATTENDED") -> 0 | U4: =COUNTIFS(clean_interactions!B:B,A4,clean_interactions!C:C,"PRICING_PAGE_VIEW") -> 0 | V4: =SUMIF(clean_spend!D:D,E4,clean_spend!F:F) -> 130023 | W4: =SUMIF(clean_spend!D:D,E4,clean_spend!J:J) -> 322 | X4: =IFERROR(V4/W4,0) -> 403.79814 | Y4: =IFERROR(SUMIF(clean_spend!D:D,E4,clean_spend!L:L)/V4,0) -> 1.3116295
A5: L0004 | B5: James Nakamura | C5: HUB SPOT | D5: STARTUP | E5: PARTNER | F5: Logistics | G5: Revops Manager | H5: Netherlands | I5: 35 | J5: 0 | K5: 7 | L5: NO | M5: NEW | N5: =IF(COUNTBLANK(clean_leads!B5:S5)>=8,"LOW",IF(COUNTBLANK(clean_leads!B5:S5)>=4,"MEDIUM","HIGH")) -> HIGH | O5: =COUNTIF(clean_interactions!B:B,A5) -> 3 | P5: =COUNTIFS(clean_interactions!B:B,A5,clean_interactions!N:N,"HIGH") -> 2 | Q5: =ROUND(SUMIF(clean_interactions!B:B,A5,clean_interactions!M:M),1) -> 44.1 | R5: =COUNTIFS(clean_interactions!B:B,A5,clean_interactions!C:C,"DEMO_REQUEST") -> 0 | S5: =COUNTIFS(clean_interactions!B:B,A5,clean_interactions!C:C,"CONTENT_DOWNLOAD") -> 0 | T5: =COUNTIFS(clean_interactions!B:B,A5,clean_interactions!C:C,"WEBINAR_ATTENDED") -> 0 | U5: =COUNTIFS(clean_interactions!B:B,A5,clean_interactions!C:C,"PRICING_PAGE_VIEW") -> 1 | V5: =SUMIF(clean_spend!D:D,E5,clean_spend!F:F) -> 0 | W5: =SUMIF(clean_spend!D:D,E5,clean_spend!J:J) -> 0 | X5: =IFERROR(V5/W5,0) -> 0 | Y5: =IFERROR(SUMIF(clean_spend!D:D,E5,clean_spend!L:L)/V5,0) -> 0
A6: L0005 | B6: Bastian Mishra | C6: DROPBOX | D6: SMB | E6: UNKNOWN | F6: Healthcare | G6: Cto | H6: AU | I6: 0 | J6: 9 | K6: 15 | L6: YES | M6: NURTURING | N6: =IF(COUNTBLANK(clean_leads!B6:S6)>=8,"LOW",IF(COUNTBLANK(clean_leads!B6:S6)>=4,"MEDIUM","HIGH")) -> HIGH | O6: =COUNTIF(clean_interactions!B:B,A6) -> 5 | P6: =COUNTIFS(clean_interactions!B:B,A6,clean_interactions!N:N,"HIGH") -> 4 | Q6: =ROUND(SUMIF(clean_interactions!B:B,A6,clean_interactions!M:M),1) -> 119.4 | R6: =COUNTIFS(clean_interactions!B:B,A6,clean_interactions!C:C,"DEMO_REQUEST") -> 1 | S6: =COUNTIFS(clean_interactions!B:B,A6,clean_interactions!C:C,"CONTENT_DOWNLOAD") -> 1 | T6: =COUNTIFS(clean_interactions!B:B,A6,clean_interactions!C:C,"WEBINAR_ATTENDED") -> 0 | U6: =COUNTIFS(clean_interactions!B:B,A6,clean_interactions!C:C,"PRICING_PAGE_VIEW") -> 0 | V6: =SUMIF(clean_spend!D:D,E6,clean_spend!F:F) -> 0 | W6: =SUMIF(clean_spend!D:D,E6,clean_spend!J:J) -> 0 | X6: =IFERROR(V6/W6,0) -> 0 | Y6: =IFERROR(SUMIF(clean_spend!D:D,E6,clean_spend!L:L)/V6,0) -> 0
A7: L0006 | B7: Yuki Robinson | C7: CLOUDFLARE | D7: SMB | E7: ORGANIC | F7: Fintech | G7: Program Manager | H7: CA | I7: 14 | J7: 0 | K7: 0 | L7: YES | M7: QUALIFIED | N7: =IF(COUNTBLANK(clean_leads!B7:S7)>=8,"LOW",IF(COUNTBLANK(clean_leads!B7:S7)>=4,"MEDIUM","HIGH")) -> HIGH | O7: =COUNTIF(clean_interactions!B:B,A7) -> 3 | P7: =COUNTIFS(clean_interactions!B:B,A7,clean_interactions!N:N,"HIGH") -> 2 | Q7: =ROUND(SUMIF(clean_interactions!B:B,A7,clean_interactions!M:M),1) -> 54.2 | R7: =COUNTIFS(clean_interactions!B:B,A7,clean_interactions!C:C,"DEMO_REQUEST") -> 0 | S7: =COUNTIFS(clean_interactions!B:B,A7,clean_interactions!C:C,"CONTENT_DOWNLOAD") -> 0 | T7: =COUNTIFS(clean_interactions!B:B,A7,clean_interactions!C:C,"WEBINAR_ATTENDED") -> 0 | U7: =COUNTIFS(clean_interactions!B:B,A7,clean_interactions!C:C,"PRICING_PAGE_VIEW") -> 1 | V7: =SUMIF(clean_spend!D:D,E7,clean_spend!F:F) -> 46997 | W7: =SUMIF(clean_spend!D:D,E7,clean_spend!J:J) -> 970 | X7: =IFERROR(V7/W7,0) -> 48.450515 | Y7: =IFERROR(SUMIF(clean_spend!D:D,E7,clean_spend!L:L)/V7,0) -> 13.49418
A8: L0007 | B8: Uriel Jensen | C8: STRIPE INC | D8: STARTUP | E8: COLD_EMAIL | F8: E-Commerce | G8: Sales Operations | H8: DE | I8: 6 | J8: 6 | K8: 8 | L8: NO | M8: ENGAGED | N8: =IF(COUNTBLANK(clean_leads!B8:S8)>=8,"LOW",IF(COUNTBLANK(clean_leads!B8:S8)>=4,"MEDIUM","HIGH")) -> HIGH | O8: =COUNTIF(clean_interactions!B:B,A8) -> 4 | P8: =COUNTIFS(clean_interactions!B:B,A8,clean_interactions!N:N,"HIGH") -> 2 | Q8: =ROUND(SUMIF(clean_interactions!B:B,A8,clean_interactions!M:M),1) -> 58.8 | R8: =COUNTIFS(clean_interactions!B:B,A8,clean_interactions!C:C,"DEMO_REQUEST") -> 0 | S8: =COUNTIFS(clean_interactions!B:B,A8,clean_interactions!C:C,"CONTENT_DOWNLOAD") -> 0 | T8: =COUNTIFS(clean_interactions!B:B,A8,clean_interactions!C:C,"WEBINAR_ATTENDED") -> 0 | U8: =COUNTIFS(clean_interactions!B:B,A8,clean_interactions!C:C,"PRICING_PAGE_VIEW") -> 2 | V8: =SUMIF(clean_spend!D:D,E8,clean_spend!F:F) -> 63789 | W8: =SUMIF(clean_spend!D:D,E8,clean_spend!J:J) -> 306 | X8: =IFERROR(V8/W8,0) -> 208.46078 | Y8: =IFERROR(SUMIF(clean_spend!D:D,E8,clean_spend!L:L)/V8,0) -> 3.061092
A9: L0008 | B9: Vivian Young | C9: GOOGLE | D9: MID-MARKET | E9: SOCIAL | F9: Automotive | G9: Intern | H9: IN | I9: 3 | J9: 17 | K9: 0 | L9: YES | M9: NEW | N9: =IF(COUNTBLANK(clean_leads!B9:S9)>=8,"LOW",IF(COUNTBLANK(clean_leads!B9:S9)>=4,"MEDIUM","HIGH")) -> HIGH | O9: =COUNTIF(clean_interactions!B:B,A9) -> 4 | P9: =COUNTIFS(clean_interactions!B:B,A9,clean_interactions!N:N,"HIGH") -> 4 | Q9: =ROUND(SUMIF(clean_interactions!B:B,A9,clean_interactions!M:M),1) -> 63.1 | R9: =COUNTIFS(clean_interactions!B:B,A9,clean_interactions!C:C,"DEMO_REQUEST") -> 0 | S9: =COUNTIFS(clean_interactions!B:B,A9,clean_interactions!C:C,"CONTENT_DOWNLOAD") -> 0 | T9: =COUNTIFS(clean_interactions!B:B,A9,clean_interactions!C:C,"WEBINAR_ATTENDED") -> 0 | U9: =COUNTIFS(clean_interactions!B:B,A9,clean_interactions!C:C,"PRICING_PAGE_VIEW") -> 0 | V9: =SUMIF(clean_spend!D:D,E9,clean_spend!F:F) -> 198205 | W9: =SUMIF(clean_spend!D:D,E9,clean_spend!J:J) -> 961 | X9: =IFERROR(V9/W9,0) -> 206.2487 | Y9: =IFERROR(SUMIF(clean_spend!D:D,E9,clean_spend!L:L)/V9,0) -> 2.4999924
A10: L0009 | B10: Elena Pandey | C10: ELASTIC | D10: SMB | E10: EVENT | F10: Legal Tech | G10: Intern | H10: N/A | I10: 19 | J10: 2 | K10: 0 | L10: NO | M10: CONVERTED | N10: =IF(COUNTBLANK(clean_leads!B10:S10)>=8,"LOW",IF(COUNTBLANK(clean_leads!B10:S10)>=4,"MEDIUM","HIGH")) -> HIGH | O10: =COUNTIF(clean_interactions!B:B,A10) -> 3 | P10: =COUNTIFS(clean_interactions!B:B,A10,clean_interactions!N:N,"HIGH") -> 3 | Q10: =ROUND(SUMIF(clean_interactions!B:B,A10,clean_interactions!M:M),1) -> 66.7 | R10: =COUNTIFS(clean_interactions!B:B,A10,clean_interactions!C:C,"DEMO_REQUEST") -> 0 | S10: =COUNTIFS(clean_interactions!B:B,A10,clean_interactions!C:C,"CONTENT_DOWNLOAD") -> 0 | T10: =COUNTIFS(clean_interactions!B:B,A10,clean_interactions!C:C,"WEBINAR_ATTENDED") -> 0 | U10: =COUNTIFS(clean_interactions!B:B,A10,clean_interactions!C:C,"PRICING_PAGE_VIEW") -> 0 | V10: =SUMIF(clean_spend!D:D,E10,clean_spend!F:F) -> 130023 | W10: =SUMIF(clean_spend!D:D,E10,clean_spend!J:J) -> 322 | X10: =IFERROR(V10/W10,0) -> 403.79814 | Y10: =IFERROR(SUMIF(clean_spend!D:D,E10,clean_spend!L:L)/V10,0) -> 1.3116295
A11: L0010 | B11: Priya Muller | C11: PALO ALTO | D11: MID-MARKET | E11: PAID | F11: Proptech | G11: Head Of Growth | H11: DE | I11: 9 | J11: 19 | K11: 21 | L11: YES | M11: NURTURING | N11: =IF(COUNTBLANK(clean_leads!B11:S11)>=8,"LOW",IF(COUNTBLANK(clean_leads!B11:S11)>=4,"MEDIUM","HIGH")) -> HIGH | O11: =COUNTIF(clean_interactions!B:B,A11) -> 5 | P11: =COUNTIFS(clean_interactions!B:B,A11,clean_interactions!N:N,"HIGH") -> 3 | Q11: =ROUND(SUMIF(clean_interactions!B:B,A11,clean_interactions!M:M),1) -> 103.7 | R11: =COUNTIFS(clean_interactions!B:B,A11,clean_interactions!C:C,"DEMO_REQUEST") -> 0 | S11: =COUNTIFS(clean_interactions!B:B,A11,clean_interactions!C:C,"CONTENT_DOWNLOAD") -> 1 | T11: =COUNTIFS(clean_interactions!B:B,A11,clean_interactions!C:C,"WEBINAR_ATTENDED") -> 0 | U11: =COUNTIFS(clean_interactions!B:B,A11,clean_interactions!C:C,"PRICING_PAGE_VIEW") -> 0 | V11: =SUMIF(clean_spend!D:D,E11,clean_spend!F:F) -> 149793 | W11: =SUMIF(clean_spend!D:D,E11,clean_spend!J:J) -> 1090 | X11: =IFERROR(V11/W11,0) -> 137.42477 | Y11: =IFERROR(SUMIF(clean_spend!D:D,E11,clean_spend!L:L)/V11,0) -> 3.4229971
A12: L0011 | B12: Landon Rossi | C12: CROWD STRIKE | D12: SMB | E12: EVENT | F12: AI/ML | G12: Growth Hacker | H12: IN | I12: 2 | J12: 6 | K12: 42 | L12: NO | M12: CONTACTED | N12: =IF(COUNTBLANK(clean_leads!B12:S12)>=8,"LOW",IF(COUNTBLANK(clean_leads!B12:S12)>=4,"MEDIUM","HIGH")) -> HIGH | O12: =COUNTIF(clean_interactions!B:B,A12) -> 8 | P12: =COUNTIFS(clean_interactions!B:B,A12,clean_interactions!N:N,"HIGH") -> 7 | Q12: =ROUND(SUMIF(clean_interactions!B:B,A12,clean_interactions!M:M),1) -> 100.3 | R12: =COUNTIFS(clean_interactions!B:B,A12,clean_interactions!C:C,"DEMO_REQUEST") -> 0 | S12: =COUNTIFS(clean_interactions!B:B,A12,clean_interactions!C:C,"CONTENT_DOWNLOAD") -> 0 | T12: =COUNTIFS(clean_interactions!B:B,A12,clean_interactions!C:C,"WEBINAR_ATTENDED") -> 1 | U12: =COUNTIFS(clean_interactions!B:B,A12,clean_interactions!C:C,"PRICING_PAGE_VIEW") -> 0 | V12: =SUMIF(clean_spend!D:D,E12,clean_spend!F:F) -> 130023 | W12: =SUMIF(clean_spend!D:D,E12,clean_spend!J:J) -> 322 | X12: =IFERROR(V12/W12,0) -> 403.79814 | Y12: =IFERROR(SUMIF(clean_spend!D:D,E12,clean_spend!L:L)/V12,0) -> 1.3116295
A13: L0012 | B13: Jamal Soto | C13: NOTION | D13: N/A | E13: COLD_EMAIL | F13: Energy | G13: Pr Manager | H13: Mexico | I13: 14 | J13: 6 | K13: 17 | L13: YES | M13: NEW | N13: =IF(COUNTBLANK(clean_leads!B13:S13)>=8,"LOW",IF(COUNTBLANK(clean_leads!B13:S13)>=4,"MEDIUM","HIGH")) -> HIGH | O13: =COUNTIF(clean_interactions!B:B,A13) -> 5 | P13: =COUNTIFS(clean_interactions!B:B,A13,clean_interactions!N:N,"HIGH") -> 4 | Q13: =ROUND(SUMIF(clean_interactions!B:B,A13,clean_interactions!M:M),1) -> 71.7 | R13: =COUNTIFS(clean_interactions!B:B,A13,clean_interactions!C:C,"DEMO_REQUEST") -> 3 | S13: =COUNTIFS(clean_interactions!B:B,A13,clean_interactions!C:C,"CONTENT_DOWNLOAD") -> 0 | T13: =COUNTIFS(clean_interactions!B:B,A13,clean_interactions!C:C,"WEBINAR_ATTENDED") -> 0 | U13: =COUNTIFS(clean_interactions!B:B,A13,clean_interactions!C:C,"PRICING_PAGE_VIEW") -> 0 | V13: =SUMIF(clean_spend!D:D,E13,clean_spend!F:F) -> 63789 | W13: =SUMIF(clean_spend!D:D,E13,clean_spend!J:J) -> 306 | X13: =IFERROR(V13/W13,0) -> 208.46078 | Y13: =IFERROR(SUMIF(clean_spend!D:D,E13,clean_spend!L:L)/V13,0) -> 3.061092
A14: L0013 | B14: Julian Shah | C14: DROPBOX | D14: STARTUP | E14: ORGANIC | F14: Cybersecurity | G14: Marketing Coordinator | H14: Ireland | I14: 34 | J14: 6 | K14: 4 | L14: NO | M14: CONTACTED | N14: =IF(COUNTBLANK(clean_leads!B14:S14)>=8,"LOW",IF(COUNTBLANK(clean_leads!B14:S14)>=4,"MEDIUM","HIGH")) -> HIGH | O14: =COUNTIF(clean_interactions!B:B,A14) -> 2 | P14: =COUNTIFS(clean_interactions!B:B,A14,clean_interactions!N:N,"HIGH") -> 2 | Q14: =ROUND(SUMIF(clean_interactions!B:B,A14,clean_interactions!M:M),1) -> 56.3 | R14: =COUNTIFS(clean_interactions!B:B,A14,clean_interactions!C:C,"DEMO_REQUEST") -> 1 | S14: =COUNTIFS(clean_interactions!B:B,A14,clean_interactions!C:C,"CONTENT_DOWNLOAD") -> 0 | T14: =COUNTIFS(clean_interactions!B:B,A14,clean_interactions!C:C,"WEBINAR_ATTENDED") -> 0 | U14: =COUNTIFS(clean_interactions!B:B,A14,clean_interactions!C:C,"PRICING_PAGE_VIEW") -> 0 | V14: =SUMIF(clean_spend!D:D,E14,clean_spend!F:F) -> 46997 | W14: =SUMIF(clean_spend!D:D,E14,clean_spend!J:J) -> 970 | X14: =IFERROR(V14/W14,0) -> 48.450515 | Y14: =IFERROR(SUMIF(clean_spend!D:D,E14,clean_spend!L:L)/V14,0) -> 13.49418
... A1001: L1000 | B1001: Leo Taylor | C1001: HUBSPOT | D1001: SMB | E1001: ORGANIC | F1001: Gaming | G1001: Marketing Operations | H1001: US | I1001: 24 | J1001: 14 | K1001: 5 | L1001: NO | M1001: DISQUALIFIED | N1001: =IF(COUNTBLANK(clean_leads!B1001:S1001)>=8,"LOW",IF(COUNTBLANK(clean_leads!B1001:S1001)>=4,"MEDIUM","HIGH")) -> HIGH | O1001: =COUNTIF(clean_interactions!B:B,A1001) -> 4 | P1001: =COUNTIFS(clean_interactions!B:B,A1001,clean_interactions!N:N,"HIGH") -> 3 | Q1001: =ROUND(SUMIF(clean_interactions!B:B,A1001,clean_interactions!M:M),1) -> 60.9 | R1001: =COUNTIFS(clean_interactions!B:B,A1001,clean_interactions!C:C,"DEMO_REQUEST") -> 0 | S1001: =COUNTIFS(clean_interactions!B:B,A1001,clean_interactions!C:C,"CONTENT_DOWNLOAD") -> 0 | T1001: =COUNTIFS(clean_interactions!B:B,A1001,clean_interactions!C:C,"WEBINAR_ATTENDED") -> 0 | U1001: =COUNTIFS(clean_interactions!B:B,A1001,clean_interactions!C:C,"PRICING_PAGE_VIEW") -> 0 | V1001: =SUMIF(clean_spend!D:D,E1001,clean_spend!F:F) -> 46997 | W1001: =SUMIF(clean_spend!D:D,E1001,clean_spend!J:J) -> 970 | X1001: =IFERROR(V1001/W1001,0) -> 48.450515 | Y1001: =IFERROR(SUMIF(clean_spend!D:D,E1001,clean_spend!L:L)/V1001,0) -> 13.49418

Sheet segment_thresholds
A1: Segment | B1: Min Score
A2: HOT | B2: 60
A3: WARM | B3: 35
A4: COLD | B4: 0

Sheet scoring_weights
A1: Metric | B1: Weight | C1: Max Raw
A2: Email Opens | B2: 10 | C2: 35
A3: Clicks | B3: 15 | C3: 20
A4: Website Visits | B4: 10 | C4: 60
A5: Demo Requested | B5: 20 | C5: 1
A6: Company Size | B6: 15 | C6: 1
A7: Engagement Score | B7: 30 | C7: 1

Sheet clean_leads
A1: lead_id | B1: name | C1: email | D1: phone | E1: company | F1: company_size | G1: source | H1: email_opens | I1: clicks | J1: website_visits | K1: demo_requested | L1: last_activity | M1: lead_status | N1: industry | O1: job_title | P1: country | Q1: annual_revenue | R1: lead_created_date | S1: linkedin_url
A2: {=raw_leads!A2:A1001} -> L0001 | B2: {=IF(TRIM(raw_leads!B2:B1001)="","Unknown",PROPER(TRIM(raw_leads!B2:B1001)))} -> Liora Jackson | C2: {=IF(TRIM(raw_leads!C2:C1001)="","missing",LOWER(TRIM(raw_leads!C2:C1001)))} -> liora.jackson@airtable.com | D2: {=IF(TRIM(raw_leads!D2:D1001)="","missing",TRIM(raw_leads!D2:D1001))} -> 232-130-2535 | E2: {=IF(TRIM(raw_leads!E2:E1001)="","UNKNOWN",UPPER(TRIM(raw_leads!E2:E1001)))} -> AIRTABLE | F2: {=IF(TRIM(raw_leads!F2:F1001)="","N/A",IF((UPPER(TRIM(raw_leads!F2:F1001))="SMALL BUSINESS")+(UPPER(TRIM(raw_leads!F2:F1001))="SMB"),"SMB",IF((UPPER(TRIM(raw_leads!F2:F1001))="MID-MARKET")+(UPPER(TRIM(raw_leads!F2:F1001))="MID MARKET"),"MID-MARKET",IF(UPPER(TRIM(raw_leads!F2:F1001))="GROWTH","GROWTH",UPPER(TRIM(raw_leads!F2:F1001))))))} -> SMB | G2: {=IF(TRIM(raw_leads!G2:G1001)="","UNKNOWN",IF((UPPER(TRIM(raw_leads!G2:G1001))="COLD EMAIL")+(UPPER(TRIM(raw_leads!G2:G1001))="COLD_EMAIL"),"COLD_EMAIL",IF((UPPER(TRIM(raw_leads!G2:G1001))="CONTENT SYNDICATION")+(UPPER(TRIM(raw_leads!G2:G1001))="CONTENT_SYNDICATION"),"CONTENT_SYNDICATION",UPPER(TRIM(raw_leads!G2:G1001)))))} -> UNKNOWN | H2: {=IF((raw_leads!H2:H1001="")+(NOT(ISNUMBER(raw_leads!H2:H1001))),0,raw_leads!H2:H1001)} -> 35 | I2: {=IF((raw_leads!I2:I1001="")+(NOT(ISNUMBER(raw_leads!I2:I1001))),0,raw_leads!I2:I1001)} -> 20 | J2: {=IF((raw_leads!J2:J1001="")+(NOT(ISNUMBER(raw_leads!J2:J1001))),0,raw_leads!J2:J1001)} -> 26 | K2: {=IF((UPPER(TRIM(raw_leads!K2:K1001))="YES")+(UPPER(TRIM(raw_leads!K2:K1001))="Y")+(UPPER(TRIM(raw_leads!K2:K1001))="TRUE")+(TRIM(raw_leads!K2:K1001)="1"),"YES","NO")} -> NO | L2: {=IF(raw_leads!L2:L1001="","",raw_leads!L2:L1001)} -> 45803 | M2: {=IF(TRIM(raw_leads!M2:M1001)="","NEW",UPPER(TRIM(raw_leads!M2:M1001)))} -> ENGAGED | N2: {=IF(TRIM(raw_leads!N2:N1001)="","Unknown",IF((UPPER(TRIM(raw_leads!N2:N1001))="ECOMMERCE")+(UPPER(TRIM(raw_leads!N2:N1001))="E-COMMERCE"),"E-Commerce",IF((UPPER(TRIM(raw_leads!N2:N1001))="AI/ML")+(UPPER(TRIM(raw_leads!N2:N1001))="AI / ML"),"AI/ML",IF((UPPER(TRIM(raw_leads!N2:N1001))="LEGALTECH")+(UPPER(TRIM(raw_leads!N2:N1001))="LEGAL TECH"),"Legal Tech",IF((UPPER(TRIM(raw_leads!N2:N1001))="SUPPLYCHAIN")+(UPPER(TRIM(raw_leads!N2:N1001))="SUPPLY CHAIN"),"Supply Chain",PROPER(TRIM(raw_leads!N2:N1001)))))))} -> Saas | O2: {=IF(TRIM(raw_leads!O2:O1001)="","Unknown",PROPER(TRIM(raw_leads!O2:O1001)))} -> Product Manager | P2: {=IF(TRIM(raw_leads!P2:P1001)="","N/A",IF((UPPER(TRIM(raw_leads!P2:P1001))="UNITED STATES")+(UPPER(TRIM(raw_leads!P2:P1001))="USA")+(UPPER(TRIM(raw_leads!P2:P1001))="US"),"US",IF((UPPER(TRIM(raw_leads!P2:P1001))="UNITED KINGDOM")+(UPPER(TRIM(raw_leads!P2:P1001))="UK"),"UK",IF((UPPER(TRIM(raw_leads!P2:P1001))="CANADA")+(UPPER(TRIM(raw_leads!P2:P1001))="CA"),"CA",IF((UPPER(TRIM(raw_leads!P2:P1001))="GERMANY")+(UPPER(TRIM(raw_leads!P2:P1001))="DE"),"DE",IF((UPPER(TRIM(raw_leads!P2:P1001))="FRANCE")+(UPPER(TRIM(raw_leads!P2:P1001))="FR"),"FR",IF((UPPER(TRIM(raw_leads!P2:P1001))="AUSTRALIA")+(UPPER(TRIM(raw_leads!P2:P1001))="AU"),"AU",IF((UPPER(TRIM(raw_leads!P2:P1001))="INDIA")+(UPPER(TRIM(raw_leads!P2:P1001))="IN"),"IN",IF((UPPER(TRIM(raw_leads!P2:P1001))="JAPAN")+(UPPER(TRIM(raw_leads!P2:P1001))="JP"),"JP",IF((UPPER(TRIM(raw_leads!P2:P1001))="BRAZIL")+(UPPER(TRIM(raw_leads!P2:P1001))="BR"),"BR",IF((UPPER(TRIM(raw_leads!P2:P1001))="SINGAPORE")+(UPPER(TRIM(raw_leads!P2:P1001))="SG"),"SG",PROPER(TRIM(raw_leads!P2:P1001)))))))))))))} -> Thailand | Q2: {=IF(TRIM(raw_leads!Q2:Q1001)="","Unknown",TRIM(raw_leads!Q2:Q1001))} -> $100M-500M | R2: {=IF(raw_leads!R2:R1001="","",raw_leads!R2:R1001)} -> 45812 | S2: {=IF(TRIM(raw_leads!S2:S1001)="","missing",LOWER(TRIM(raw_leads!S2:S1001)))} -> missing
A3: L0002 | B3: Yara Malik | C3: yara.malik@airtable.com | D3: missing | E3: AIRTABLE | F3: SMB | G3: EVENT | H3: 4 | I3: 0 | J3: 18 | K3: YES | L3: 45701 | M3: QUALIFIED | N3: Retail | O3: Sales Engineer | P3: IN | Q3: $1B+ | R3: 46013 | S3: linkedin.com/in/dashiellpopov22
A4: L0003 | B4: Luna Harris | C4: luna.harris@crowdstrike.com | D4: 434.941.1525 | E4: CROWD STRIKE | F4: SMB | G4: EVENT | H4: 13 | I4: 18 | J4: 20 | K4: YES | L4: 45859 | M4: QUALIFIED | N4: AI/ML | O4: Business Development Rep | P4: AU | Q4: $50M - $100M | R4: 46010 | S4: https://linkedin.com/in/xylanguyen47
A5: L0004 | B5: James Nakamura | C5: james.nakamura@hubspot.com | D5: missing | E5: HUB SPOT | F5: STARTUP | G5: PARTNER | H5: 35 | I5: 0 | J5: 7 | K5: NO | L5: 45802 | M5: NEW | N5: Logistics | O5: Revops Manager | P5: Netherlands | Q5: Unknown | S5: https://linkedin.com/in/ravischneider98
A6: L0005 | B6: Bastian Mishra | C6: bastian.mishra@dropbox.com | D6: +1-997-643-1009 | E6: DROPBOX | F6: SMB | G6: UNKNOWN | H6: 0 | I6: 9 | J6: 15 | K6: YES | L6: 45712 | M6: NURTURING | N6: Healthcare | O6: Cto | P6: AU | Q6: $50M - $100M | R6: 45928 | S6: linkedin.com/in/deepasaxena70
A7: L0006 | B7: Yuki Robinson | C7: yuki.robinson@cloudflare.com | D7: missing | E7: CLOUDFLARE | F7: SMB | G7: ORGANIC | H7: 14 | I7: 0 | J7: 0 | K7: YES | M7: QUALIFIED | N7: Fintech | O7: Program Manager | P7: CA | Q7: 1M-10M | R7: 45765 | S7: missing
A8: L0007 | B8: Uriel Jensen | C8: uriel.jensen@stripeinc.com | D8: (946) 155-2612 | E8: STRIPE INC | F8: STARTUP | G8: COLD_EMAIL | H8: 6 | I8: 6 | J8: 8 | K8: NO | L8: 45877 | M8: ENGAGED | N8: E-Commerce | O8: Sales Operations | P8: DE | Q8: Unknown | R8: 45660 | S8: www.linkedin.com/in/jasminesanchez53
A9: L0008 | B9: Vivian Young | C9: vivian.young@google.com | D9: 633-813-8973 | E9: GOOGLE | F9: MID-MARKET | G9: SOCIAL | H9: 3 | I9: 17 | J9: 0 | K9: YES | M9: NEW | N9: Automotive | O9: Intern | P9: IN | Q9: Unknown | R9: 45719 | S9: www.linkedin.com/in/umbraiyer31
A10: L0009 | B10: Elena Pandey | C10: elena.pandey@elastic.com | D10: 467-309-6147 | E10: ELASTIC | F10: SMB | G10: EVENT | H10: 19 | I10: 2 | J10: 0 | K10: NO | L10: 45691 | M10: CONVERTED | N10: Legal Tech | O10: Intern | P10: N/A | Q10: Unknown | R10: 45696 | S10: missing
A11: L0010 | B11: Priya Muller | C11: priya.muller@paloalto.com | D11: 3069993200 | E11: PALO ALTO | F11: MID-MARKET | G11: PAID | H11: 9 | I11: 19 | J11: 21 | K11: YES | L11: 45794 | M11: NURTURING | N11: Proptech | O11: Head Of Growth | P11: DE | Q11: Series C+ | R11: 45668 | S11: linkedin.com/in/liorascott21
A12: L0011 | B12: Landon Rossi | C12: landon.rossi@crowdstrike.com | D12: (351) 540-3088 | E12: CROWD STRIKE | F12: SMB | G12: EVENT | H12: 2 | I12: 6 | J12: 42 | K12: NO | L12: 45928 | M12: CONTACTED | N12: AI/ML | O12: Growth Hacker | P12: IN | Q12: Series B | R12: 45839 | S12: missing
A13: L0012 | B13: Jamal Soto | C13: jamal.soto@notion.com | D13: 681.327.4269 | E13: NOTION | F13: N/A | G13: COLD_EMAIL | H13: 14 | I13: 6 | J13: 17 | K13: YES | L13: 45789 | M13: NEW | N13: Energy | O13: Pr Manager | P13: Mexico | Q13: $50M-100M | R13: 45783 | S13: linkedin.com/in/ravijones14
A14: L0013 | B14: Julian Shah | C14: julian.shah@dropbox.com | D14: missing | E14: DROPBOX | F14: STARTUP | G14: ORGANIC | H14: 34 | I14: 6 | J14: 4 | K14: NO | L14: 45941 | M14: CONTACTED | N14: Cybersecurity | O14: Marketing Coordinator | P14: Ireland | Q14: 50M+ | R14: 45795 | S14: missing
A15: L0014 | B15: Finn Torres | C15: finn.torres@databricks.com | D15: +14155406279 | E15: DATABRICKS | F15: N/A | G15: PARTNER | H15: 32 | I15: 5 | J15: 18 | K15: YES | L15: 45941 | M15: QUALIFIED | N15: Insurtech | O15: Marketing Analyst | P15: BR | Q15: $100M-500M | S15: missing
A16: L0015 | B16: Tatiana Dubois | C16: tatiana.dubois@elastic.com | D16: 351.771.1090 | E16: ELASTIC | F16: MID-MARKET | G16: CONTENT_SYNDICATION | H16: 33 | I16: 17 | J16: 54 | K16: NO | L16: 45891 | M16: LOST | N16: Unknown | O16: Sales Operations | P16: Thailand | Q16: $50M - $100M | R16: 45740 | S16: https://linkedin.com/in/nicoscott97
A17: L0016 | B17: Liora Adams | C17: liora.adams@datadog.com | D17: 753-182-3267 | E17: DATADOG | F17: SMB | G17: EVENT | H17: 13 | I17: 0 | J17: 34 | K17: NO | L17: 45774 | M17: CONTACTED | N17: Supply Chain | O17: Cmo | P17: South Africa | Q17: < $1M | R17: 45866 | S17: linkedin.com/in/finnolsen96
A18: L0017 | B18: Margaux Aguilar | C18: margaux.aguilar@asana.com | D18: 941-269-8657 | E18: ASANA | F18: MID-MARKET | G18: DIRECT | H18: 0 | I18: 18 | J18: 5 | K18: YES | L18: 45875 | M18: CONTACTED | N18: Cleantech | O18: Channel Manager | P18: South Korea | Q18: 50M+ | R18: 45847 | S18: www.linkedin.com/in/finnhill11
A19: L0018 | B19: Eve Mendoza | C19: missing | D19: missing | E19: SPLUNK | F19: SMB | G19: WEBINAR | H19: 9 | I19: 15 | J19: 36 | K19: YES | L19: 45802 | M19: CONVERTED | N19: Martech | O19: Revops Manager | P19: IN | Q19: $50M-100M | R19: 45796 | S19: https://linkedin.com/in/umaro'brien92
A20: L0019 | B20: Tina Petrov | C20: tina.petrov@linear.com | D20: 7799011672 | E20: LINEAR | F20: ENTERPRISE | G20: CONTENT_SYNDICATION | H20: 4 | I20: 10 | J20: 0 | K20: NO | L20: 45702 | M20: CONVERTED | N20: Retail | O20: Co-Founder | P20: Vietnam | Q20: $1M - $10M | R20: 45797 | S20: www.linkedin.com/in/kaiavega62
A21: L0020 | B21: Julian Mehta | C21: julian.mehta@microsoft.com | D21: (884) 488-6511 | E21: MICROSOFT | F21: N/A | G21: COLD_EMAIL | H21: 13 | I21: 8 | J21: 56 | K21: NO | L21: 45795 | M21: NEW | N21: Hrtech | O21: Sdr Manager | P21: BR | Q21: Unknown | R21: 45770 | S21: linkedin.com/in/xiomarajohansson3
A22: L0021 | B22: Zachary Allen | C22: zachary.allen@cloudflare.com | D22: 5384608434 | E22: CLOUDFLARE | F22: SMB | G22: SOCIAL | H22: 12 | I22: 17 | J22: 44 | K22: NO | L22: 46007 | M22: QUALIFIED | N22: Biotech | O22: Head Of Sales | P22: SG | Q22: < $1M | R22: 45680 | S22: linkedin.com/in/ursulagarcia7
A23: L0022 | B23: Yvonne Diaz | C23: yvonne.diaz@microsoftcorp.com | D23: 388.152.5136 | E23: MICROSOFT CORP | F23: N/A | G23: PAID | H23: 25 | I23: 18 | J23: 3 | K23: NO | L23: 45940 | M23: QUALIFIED | N23: Proptech | O23: Ceo | P23: Indonesia | Q23: Series B | R23: 45913 | S23: www.linkedin.com/in/landonnelson76
A24: L0023 | B24: Camila Decker | C24: camila.decker@linear.com | D24: missing | E24: LINEAR | F24: MID-MARKET | G24: DIRECT | H24: 0 | I24: 0 | J24: 38 | K24: NO | L24: 45757 | M24: DISQUALIFIED | N24: Biotech | O24: Chief Growth Officer | P24: CA | Q24: 1M-10M | R24: 45980 | S24: linkedin.com/in/zarapark15
A25: L0024 | B25: George Reyes | C25: george.reyes@amazon.com | D25: +14955493037 | E25: AMAZON | F25: GROWTH | G25: COLD_EMAIL | H25: 17 | I25: 15 | J25: 38 | K25: YES | L25: 46002 | M25: NEW | N25: Proptech | O25: Director Of Marketing | P25: DE | Q25: $5M-$25M | R25: 45949 | S25: linkedin.com/in/umbramehta35
A26: L0025 | B26: Karen Ortiz | C26: karen.ortiz@datadog.com | D26: +12935816700 | E26: DATADOG | F26: SMB | G26: COLD_EMAIL | H26: 10 | I26: 15 | J26: 60 | K26: NO | L26: 45902 | M26: QUALIFIED | N26: E-Commerce | O26: Data Analyst | P26: N/A | Q26: Series A | R26: 45927 | S26: www.linkedin.com/in/quinlanbose70
A27: L0026 | B27: Dante Martinez | C27: dante.martinez@elastic.com | D27: missing | E27: ELASTIC | F27: SMB | G27: PARTNER | H27: 31 | I27: 20 | J27: 15 | K27: NO | L27: 45675 | M27: CONTACTED | N27: E-Commerce | O27: Digital Marketing Manager | P27: FR | Q27: $50M-100M | R27: 45732 | S27: https://www.linkedin.com/in/yvonnenakamura91
... A38: L0037 | B38: Nico Kapoor | C38: nico.kapoor@zendesk.com | D38: (356) 803-8770 | E38: ZENDESK | F38: ENTERPRISE | G38: PAID | H38: 0 | I38: 0 | J38: 51 | K38: NO | L38: 45948 | M38: CONVERTED | N38: Fintech | O38: Ceo | P38: Colombia | Q38: $5M-$25M | R38: 45866 | S38: linkedin.com/in/nickmalhotra37
A39: L0038 | B39: Dmitri Malik | C39: dmitri.malik@freshworks.com | D39: 980.385.4705 | E39: FRESHWORKS | F39: STARTUP | G39: DIRECT | H39: 35 | I39: 0 | J39: 53 | K39: YES | M39: QUALIFIED | N39: Unknown | O39: Technical Lead | P39: Italy | Q39: Unknown | R39: 45952 | S39: linkedin.com/in/kiraguerrero82
A40: L0039 | B40: Xander Mendoza | C40: xander.mendoza@slack.com | D40: 286-153-3549 | E40: SLACK | F40: MID-MARKET | G40: ORGANIC | H40: 17 | I40: 13 | J40: 28 | K40: NO | L40: 45904 | M40: CONVERTED | N40: Telecom | O40: Revops Manager | P40: UK | Q40: $100M+ | R40: 45971 | S40: missing
A41: L0040 | B41: Zion Novak | C41: zion.novak@linear.com | D41: missing | E41: LINEAR | F41: GROWTH | G41: CONTENT_SYNDICATION | H41: 24 | I41: 7 | J41: 53 | K41: NO | L41: 45701 | M41: ENGAGED | N41: Fintech | O41: Marketing Operations | P41: US | Q41: $10M-50M | R41: 45944 | S41: linkedin.com/in/liorachen38
A42: L0041 | B42: Bennett Williams | C42: bennett.williams@docusign.com | D42: +1-449-546-7560 | E42: DOCUSIGN | F42: ENTERPRISE | G42: EVENT | H42: 21 | I42: 5 | J42: 0 | K42: YES | L42: 45907 | M42: DISQUALIFIED | N42: Logistics | O42: Engineering Manager | P42: AU | Q42: $100M-500M | R42: 45736 | S42: missing
A43: L0042 | B43: Perseus Wilson | C43: perseus.wilson@miro.com | D43: 858.750.6295 | E43: MIRO | F43: ENTERPRISE | G43: COLD_EMAIL | H43: 4 | I43: 20 | J43: 17 | K43: YES | M43: LOST | N43: E-Commerce | O43: Marketing Analyst | P43: Bangladesh | Q43: $1M-10M | R43: 45780 | S43: linkedin.com/in/xanderdubois77
A44: L0043 | B44: Winston Costa | C44: winston.costa@meta.com | D44: (687) 613-3471 | E44: META | F44: N/A | G44: PAID | H44: 21 | I44: 2 | J44: 11 | K44: YES | L44: 45884 | M44: LOST | N44: AI/ML | O44: Sales Engineer | P44: Saudi Arabia | Q44: $10M+ | R44: 45830 | S44: linkedin.com/in/juniperreyes43
A45: L0044 | B45: Isla Taylor | C45: isla.taylor@paloaltonetworks.com | D45: missing | E45: PALO ALTO NETWORKS | F45: MID-MARKET | G45: REFERRAL | H45: 19 | I45: 12 | J45: 45 | K45: YES | L45: 45859 | M45: ENGAGED | N45: Fintech | O45: Cto | P45: DE | Q45: unknown | R45: 45669 | S45: missing
A46: L0045 | B46: Deepa Ali | C46: deepa.ali@hubspot.com | D46: (752) 955-9626 | E46: HUBSPOT | F46: MID-MARKET | G46: COLD_EMAIL | H46: 8 | I46: 4 | J46: 53 | K46: NO | L46: 45740 | M46: QUALIFIED | N46: Fintech | O46: Events Manager | P46: Uae | Q46: 0-1M | R46: 45940 | S46: https://linkedin.com/in/marisolking69
A47: L0046 | B47: Dmitri Malhotra | C47: dmitri.malhotra@cloudflare.com | D47: +1-996-491-9239 | E47: CLOUDFLARE | F47: STARTUP | G47: REFERRAL | H47: 8 | I47: 1 | J47: 55 | K47: YES | L47: 45711 | M47: ENGAGED | N47: Cybersecurity | O47: Vp Sales | P47: DE | Q47: 1M-10M | R47: 45905 | S47: www.linkedin.com/in/xanderverma29
A48: L0047 | B48: Nolan Tiwari | C48: nolan.tiwari@notion.com | D48: 301.959.6493 | E48: NOTION | F48: MID-MARKET | G48: REFERRAL | H48: 0 | I48: 15 | J48: 8 | K48: NO | L48: 45660 | M48: NEW | N48: Proptech | O48: Director Of Demand Gen | P48: IN | Q48: self-funded | R48: 45842 | S48: linkedin.com/in/jasminenelson16
A49: L0048 | B49: Kevin Chen | C49: kevin.chen@canva.com | D49: missing | E49: CANVA | F49: MID-MARKET | G49: SOCIAL | H49: 22 | I49: 13 | J49: 42 | K49: YES | L49: 45811 | M49: LOST | N49: Energy | O49: Intern | P49: US | Q49: Unknown | S49: missing
A50: L0049 | B50: Thea Hill | C50: thea.hill@notion.com | D50: 5402361726 | E50: NOTION | F50: ENTERPRISE | G50: COLD_EMAIL | H50: 11 | I50: 14 | J50: 30 | K50: YES | L50: 45719 | M50: DISQUALIFIED | N50: Retail | O50: Growth Lead | P50: Netherlands | Q50: Series B | R50: 45668 | S50: www.linkedin.com/in/doriano'brien70
...

Sheet clean_spend
A1: campaign_id | B1: campaign_name | C1: campaign_desc | D1: source | E1: channel | F1: monthly_spend | G1: month | H1: impressions | I1: clicks_generated | J1: leads_generated | K1: conversions | L1: revenue_attributed | M1: cost_per_lead | N1: cost_per_click | O1: click_through_rate | P1: conversion_rate | Q1: ROAS
A2: {=raw_spend!A2:A136} -> C007 | B2: {=IF(raw_spend!A2:A136="C001","Google Ads - Search",IF(raw_spend!A2:A136="C002","Google Ads - Display",IF(raw_spend!A2:A136="C003","Meta - Brand Awareness",IF(raw_spend!A2:A136="C004","LinkedIn - ABM Campaign",IF(raw_spend!A2:A136="C005","Webinar Series",IF(raw_spend!A2:A136="C006","Referral Program",IF(raw_spend!A2:A136="C007","SEO Content Program",IF(raw_spend!A2:A136="C008","Cold Email Outbound",IF(raw_spend!A2:A136="C009","Trade Show Circuit",IF(raw_spend!A2:A136="C010","Content Syndication","UNKNOWN"))))))))))} -> SEO Content Program | C2: {=IF(TRIM(raw_spend!C2:C136)="","Unknown",PROPER(TRIM(raw_spend!C2:C136)))} -> Seo Content Program | D2: {=IF(TRIM(raw_spend!D2:D136)="","UNKNOWN",IF((UPPER(TRIM(raw_spend!D2:D136))="COLD EMAIL")+(UPPER(TRIM(raw_spend!D2:D136))="COLD_EMAIL"),"COLD_EMAIL",IF((UPPER(TRIM(raw_spend!D2:D136))="CONTENT SYNDICATION")+(UPPER(TRIM(raw_spend!D2:D136))="CONTENT_SYNDICATION"),"CONTENT_SYNDICATION",UPPER(TRIM(raw_spend!D2:D136)))))} -> ORGANIC | E2: {=IF(TRIM(raw_spend!E2:E136)="","UNKNOWN",IF((UPPER(TRIM(raw_spend!E2:E136))="FB/IG")+(UPPER(TRIM(raw_spend!E2:E136))="META")+(UPPER(TRIM(raw_spend!E2:E136))="FACEBOOK/INSTAGRAM"),"Facebook/Instagram",IF((UPPER(TRIM(raw_spend!E2:E136))="BLOG/SEO")+(UPPER(TRIM(raw_spend!E2:E136))="BLOG"),"Blog/SEO",IF((UPPER(TRIM(raw_spend!E2:E136))="3RD PARTY")+(UPPER(TRIM(raw_spend!E2:E136))="THIRD PARTY"),"3rd Party",IF(UPPER(TRIM(raw_spend!E2:E136))="OWNED MEDIA","Owned Media",PROPER(TRIM(raw_spend!E2:E136)))))))} -> Blog/SEO | F2: {=raw_spend!F2:F136} -> 4423 | G2: {=raw_spend!G2:G136} -> 2025-12 | H2: {=raw_spend!H2:H136} -> 108294 | I2: {=raw_spend!I2:I136} -> 5972 | J2: {=raw_spend!J2:J136} -> 99 | K2: {=raw_spend!K2:K136} -> 21 | L2: {=raw_spend!L2:L136} -> 77911 | M2: {=IFERROR(raw_spend!F2:F136/raw_spend!J2:J136,0)} -> 44.676768 | N2: {=IFERROR(raw_spend!F2:F136/raw_spend!I2:I136,0)} -> 0.74062291 | O2: {=IFERROR(raw_spend!I2:I136/raw_spend!H2:H136,0)} -> 0.055146176 | P2: {=IFERROR(raw_spend!K2:K136/raw_spend!J2:J136,0)} -> 0.21212121 | Q2: {=IFERROR(raw_spend!L2:L136/raw_spend!F2:F136,0)} -> 17.614967
A3: C001 | B3: Google Ads - Search | C3: Google Ads — Search | D3: PAID | E3: Search | F3: 6401 | G3: 2025-01 | H3: 61308 | I3: 2283 | J3: 48 | K3: 5 | L3: 12313 | M3: 133.35417 | N3: 2.803767 | O3: 0.037238207 | P3: 0.10416667 | Q3: 1.9236057
A4: C001 | B4: Google Ads - Search | C4: Google Ads — Search | D4: PAID | E4: Search | F4: 6171 | G4: 2025-02 | H4: 54265 | I4: 1683 | J4: 34 | K4: 7 | L4: 33082 | M4: 181.5 | N4: 3.6666667 | O4: 0.031014466 | P4: 0.20588235 | Q4: 5.3608815
A5: C001 | B5: Google Ads - Search | C5: Google Ads — Search | D5: PAID | E5: Search | F5: 6022 | G5: 2025-03 | H5: 45356 | I5: 1769 | J5: 36 | K5: 10 | L5: 24392 | M5: 167.27778 | N5: 3.4041832 | O5: 0.039002558 | P5: 0.27777778 | Q5: 4.0504816
A6: C001 | B6: Google Ads - Search | C6: Google Ads — Search | D6: PAID | E6: Search | F6: 6863 | G6: 2025-04 | H6: 62990 | I6: 2113 | J6: 48 | K6: 6 | L6: 9330 | M6: 142.97917 | N6: 3.2479886 | O6: 0.033545007 | P6: 0.125 | Q6: 1.3594638
A7: C001 | B7: Google Ads - Search | C7: Google Ads — Search | D7: PAID | E7: Search | F7: 6982 | G7: 2025-05 | H7: 49599 | I7: 2197 | J7: 60 | K7: 7 | L7: 11457 | M7: 116.36667 | N7: 3.17797 | O7: 0.044295248 | P7: 0.11666667 | Q7: 1.6409338
A8: C001 | B8: Google Ads - Search | C8: Google Ads — Search | D8: PAID | E8: Search | F8: 6013 | G8: 2025-06 | H8: 56402 | I8: 1617 | J8: 48 | K8: 10 | L8: 17657 | M8: 125.27083 | N8: 3.7186147 | O8: 0.028669196 | P8: 0.20833333 | Q8: 2.936471
A9: C006 | B9: Referral Program | C9: Referral Program | D9: REFERRAL | E9: Partner | F9: 2199 | G9: 2025-03 | H9: 5080 | I9: 1128 | J9: 56 | K9: 12 | L9: 19507 | M9: 39.267857 | N9: 1.9494681 | O9: 0.22204724 | P9: 0.21428571 | Q9: 8.8708504
A10: C001 | B10: Google Ads - Search | C10: Google Ads — Search | D10: PAID | E10: Search | F10: 6560 | G10: 2025-07 | H10: 48495 | I10: 2278 | J10: 61 | K10: 12 | L10: 38764 | M10: 107.54098 | N10: 2.8797191 | O10: 0.046973915 | P10: 0.19672131 | Q10: 5.9091463
A11: C001 | B11: Google Ads - Search | C11: Google Ads — Search | D11: PAID | E11: Search | F11: 6885 | G11: 2025-08 | H11: 62783 | I11: 2670 | J11: 56 | K11: 6 | L11: 26525 | M11: 122.94643 | N11: 2.5786517 | O11: 0.042527436 | P11: 0.10714286 | Q11: 3.8525781
A12: C001 | B12: Google Ads - Search | C12: Google Ads — Search | D12: PAID | E12: Search | F12: 7831 | G12: 2025-09 | H12: 72266 | I12: 2799 | J12: 63 | K12: 14 | L12: 39525 | M12: 124.30159 | N12: 2.7977849 | O12: 0.038731907 | P12: 0.22222222 | Q12: 5.0472481
A13: C001 | B13: Google Ads - Search | C13: Google Ads — Search | D13: PAID | E13: Search | F13: 9046 | G13: 2025-10 | H13: 66262 | I13: 2551 | J13: 85 | K13: 9 | L13: 10705 | M13: 106.42353 | N13: 3.5460604 | O13: 0.038498687 | P13: 0.10588235 | Q13: 1.183396
A14: C001 | B14: Google Ads - Search | C14: Google Ads — Search | D14: PAID | E14: Search | F14: 8538 | G14: 2025-11 | H14: 60811 | I14: 2325 | J14: 71 | K14: 10 | L14: 44184 | M14: 120.25352 | N14: 3.6722581 | O14: 0.038233214 | P14: 0.14084507 | Q14: 5.1749824
... A136: C010 | B136: Content Syndication | C136: Content Syndication | D136: CONTENT_SYNDICATION | E136: 3rd Party | F136: 5929 | G136: 2025-12 | H136: 40080 | I136: 1247 | J136: 27 | K136: 2 | L136: 4823 | M136: 219.59259 | N136: 4.7546111 | O136: 0.031112774 | P136: 0.074074074 | Q136: 0.81345927

Sheet clean_interactions
A1: interaction_id | B1: lead_id | C1: interaction_type | D1: interaction_date | E1: channel | F1: campaign_id | G1: content_asset | H1: response | I1: time_spent_seconds | J1: device | K1: page_url | L1: notes | M1: time_spent_minutes | N1: engagement_level
A2: {=raw_interactions!A2:A3001} -> INT-00001 | B2: {=raw_interactions!B2:B3001} -> L0268 | C2: {=IF(TRIM(raw_interactions!C2:C3001)="","UNKNOWN",UPPER(SUBSTITUTE(TRIM(raw_interactions!C2:C3001)," ","_")))} -> CASE_STUDY_VIEW | D2: {=IF(raw_interactions!D2:D3001="","",raw_interactions!D2:D3001)} -> 45939 | E2: {=IF(TRIM(raw_interactions!E2:E3001)="","UNKNOWN",IF((UPPER(TRIM(raw_interactions!E2:E3001))="IN-PERSON")+(UPPER(TRIM(raw_interactions!E2:E3001))="IN PERSON"),"IN-PERSON",IF(UPPER(TRIM(raw_interactions!E2:E3001))="PUSH_NOTIFICATION","PUSH_NOTIFICATION",UPPER(TRIM(raw_interactions!E2:E3001)))))} -> SOCIAL | F2: {=IF(TRIM(raw_interactions!F2:F3001)="","N/A",UPPER(TRIM(raw_interactions!F2:F3001)))} -> C007 | G2: {=IF(TRIM(raw_interactions!G2:G3001)="","Unknown",PROPER(TRIM(raw_interactions!G2:G3001)))} -> Newsletter Issue #42 | H2: {=IF(TRIM(raw_interactions!H2:H3001)="","NO_RESPONSE",IF(UPPER(TRIM(raw_interactions!H2:H3001))="PARTIAL_VIEW","PARTIAL_VIEW",UPPER(SUBSTITUTE(TRIM(raw_interactions!H2:H3001)," ","_"))))} -> DOWNLOADED | I2: {=IF((raw_interactions!I2:I3001="")+(NOT(ISNUMBER(raw_interactions!I2:I3001))),0,raw_interactions!I2:I3001)} -> 1508 | J2: {=IF(TRIM(raw_interactions!J2:J3001)="","UNKNOWN",IF((UPPER(TRIM(raw_interactions!J2:J3001))="IOS")+(UPPER(TRIM(raw_interactions!J2:J3001))="ANDROID"),"MOBILE",IF((UPPER(TRIM(raw_interactions!J2:J3001))="WINDOWS")+(UPPER(TRIM(raw_interactions!J2:J3001))="MAC"),"DESKTOP",UPPER(TRIM(raw_interactions!J2:J3001)))))} -> MOBILE | K2: {=IF(TRIM(raw_interactions!K2:K3001)="","N/A",LOWER(TRIM(raw_interactions!K2:K3001)))} -> https://example.com/case-studies | L2: {=IF(TRIM(raw_interactions!L2:L3001)="","",PROPER(TRIM(raw_interactions!L2:L3001)))} | M2: {=IFERROR(IF((raw_interactions!I2:I3001="")+(NOT(ISNUMBER(raw_interactions!I2:I3001))),0,ROUND(raw_interactions!I2:I3001/60,1)),0)} -> 25.1 | N2: {=IF((raw_interactions!I2:I3001="")+(NOT(ISNUMBER(raw_interactions!I2:I3001))),"NONE",IF(raw_interactions!I2:I3001>=300,"HIGH",IF(raw_interactions!I2:I3001>=60,"MEDIUM","LOW")))} -> HIGH
A3: INT-00002 | B3: L0445 | C3: FORM_SUBMIT | D3: 45803 | E3: SOCIAL | F3: C003 | G3: 10 Lead Scoring Tips | H3: CLICKED | I3: 362 | J3: DESKTOP | K3: N/A | M3: 6 | N3: HIGH
A4: INT-00003 | B4: L0257 | C4: CHATBOT_CONVO | D4: 45813 | E4: EMAIL | F4: C004 | G4: Event Registration: Summit 2025 | H4: BOUNCED | I4: 382 | J4: DESKTOP | K4: N/A | M4: 6.4 | N4: HIGH
A5: INT-00004 | B5: L0967 | C5: FREE_TRIAL_SIGNUP | E5: PHONE | F5: C007 | G5: Case Study: Smb Growth Story | H5: BOUNCED | I5: 0 | J5: TABLET | K5: https://example.com/integrations | M5: 0 | N5: NONE
A6: INT-00005 | B6: L0561 | C6: CONTENT_DOWNLOAD | E6: EMAIL | F6: N/A | G6: Newsletter Issue #44 | H6: REGISTERED | I6: 764 | J6: DESKTOP | K6: N/A | M6: 12.7 | N6: HIGH
A7: INT-00006 | B7: L0488 | C7: UNSUBSCRIBE | D7: 45998 | E7: WEB | F7: C008 | G7: Crm Buyer'S Guide 2025 | H7: NO_RESPONSE | I7: 1146 | J7: MOBILE | K7: https://example.com/free-trial | M7: 19.1 | N7: HIGH
A8: INT-00007 | B8: L0099 | C8: EMAIL_OPEN | D8: 46017 | E8: IN-PERSON | F8: C010 | G8: Product Demo Video | H8: NO_RESPONSE | I8: 180 | J8: DESKTOP | K8: https://example.com/blog | M8: 3 | N8: MEDIUM
